<?xml version="1.0" encoding="utf-8"?>
<!-- This URDF was automatically created by SolidWorks to URDF Exporter! Originally created by Stephen Brawner (brawner@gmail.com) 
     Commit Version: 1.6.0-1-g15f4949  Build Version: 1.6.7594.29634
     For more information, please see http://wiki.ros.org/sw_urdf_exporter -->
<robot name="model_door2">
  <link name="base_link">
    <!-- <inertial>
      <origin
        xyz="0.60009 0.030005 1"
        rpy="0 0 0" />
      <mass
        value="143.97" />
      <inertia
        ixx="48.043"
        ixy="0.00031815"
        ixz="-6.9402E-19"
        iyy="65.274"
        iyz="-2.9364E-15"
        izz="17.317" />
    </inertial> -->
    <visual>
      <origin xyz="0 0 0" rpy="0 0 0" />
      <geometry>
        <mesh filename="package://model_door2/meshes/base_link.STL" />
      </geometry>
      <material name="Front">
        <color rgba="1 1 1 1" />
      </material>
    </visual>
    <!-- <collision>
      <origin xyz="0 0 0" rpy="0 0 0" />
      <geometry>
        <mesh filename="package://model_door2/meshes/base_link.STL" />
      </geometry>
    </collision> -->
  </link>
  <link name="link1">
    <inertial>
      <!-- <origin xyz="0.022886 0 0.017832" rpy="0 0 0" /> -->
      <origin xyz="0.0 0.0 0.0" rpy="0 0 0" />

      <!-- <mass
        value="0.8344" /> -->
      <mass
        value="0.03" />
      <inertia
        ixx="0.00054037"
        ixy="-1.2285E-20"
        ixz="-0.00049637"
        iyy="0.0017352"
        iyz="-9.7971E-21"
        izz="0.0014255" />
    </inertial>
    <visual>
      <!-- <origin xyz="0.08 0.0 0.09" rpy="0 1.57 0" /> -->
      <origin xyz="0.00 0.0 0.00" rpy="0 0 0" />

      <geometry>
        <mesh filename="package://model_door2/meshes/link1.STL" />
        <!-- <box size="0.15 0.018 0.018"/> -->
        <!-- <cylinder radius="0.009" length="0.25" /> -->
      </geometry>
      <material name="Front">
        <color rgba="1 0.87 0.68 1" />
      </material>
    </visual>
    
    <collision>
      <origin xyz="0.08 0.0 0.09" rpy="0 0 0" />
      <geometry>
        <!-- <mesh filename="package://model_door2/meshes/link1.STL" /> -->
        <!-- <box size="0.15 0.018 0.018"/> -->
        <!-- <box size="0.25 0.018 0.018"/> -->

        
        <cylinder radius="0.009" length="0.15" />
      </geometry>
    </collision>
  </link>
  <joint name="joint1" type="revolute">
    <origin xyz="0.15 0 1" rpy="1.5708 0 0" />
    <parent link="base_link" />
    <child link="link1" />
    <axis xyz="0 0 -1" />
    <limit lower="0" upper="1.047" effort="100" velocity="1" />
    <!-- <dynamics damping="0" friction="0.0"/>
     -->
    <friction>
      <ode>
        <mu>0.3</mu>  <!-- Coulomb摩擦系数 -->
        <mu2>0.2</mu2>  <!-- 第二摩擦系数 -->
        <fdir1>0 0 1</fdir1>  <!-- 摩擦方向 -->
      </ode>
    </friction>
  </joint>
</robot>