<?xml version="1.0" encoding="utf-8"?>
<!-- This URDF was automatically created by SolidWorks to URDF Exporter! Originally created by Stephen Brawner (brawner@gmail.com) 
     Commit Version: 1.6.0-4-g7f85cfe  Build Version: 1.6.7995.38578
     For more information, please see http://wiki.ros.org/sw_urdf_exporter -->
<robot
  name="model_door">
  <link
    name="base_link">
    <inertial>
      <origin
        xyz="-0.025 0.50036 1"
        rpy="0 0 0" />
      <mass
        value="849.32" />
      <inertia
        ixx="354.03"
        ixy="9.0062E-19"
        ixz="6.2498E-35"
        iyy="283.51"
        iyz="1.0561E-17"
        izz="70.873" />
    </inertial>
    <visual>
      <origin
        xyz="0 0 0"
        rpy="0 0 0" />
      <geometry>
        <mesh
          filename="package://model_door/meshes/base_link.STL" />
      </geometry>
      <material
        name="">
        <color
          rgba="0.64706 0.51765 0 1" />
      </material>
    </visual>
    <collision>
      <origin
        xyz="0 0 0"
        rpy="0 0 0" />
      <geometry>
        <mesh
          filename="package://model_door/meshes/base_link.STL" />
      </geometry>
    </collision>
  </link>
  <link
    name="link1">
    <inertial>
      <origin
        xyz="0.05023 0.023148 -1.1102E-16"
        rpy="0 0 0" />
      <mass
        value="1.0044" />
      <inertia
        ixx="0.001942"
        ixy="-0.0010302"
        ixz="-1.3476E-22"
        iyy="0.0013227"
        iyz="-3.3834E-21"
        izz="0.003092" />
    </inertial>
    <visual>
      <origin
        xyz="0 0 0"
        rpy="0 0 0" />
      <geometry>
        <mesh
          filename="package://model_door/meshes/link1.STL" />
      </geometry>
      <material
        name="">
        <color
          rgba="0.52941 0.54902 0.54902 1" />
      </material>
    </visual>
    <collision>
      <origin
        xyz="0 0 0"
        rpy="0 0 0" />
      <geometry>
        <mesh
          filename="package://model_door/meshes/link1.STL" />
      </geometry>
    </collision>
  </link>
  <joint
    name="joint1"
    type="revolute">
    <origin
      xyz="-0.05 0.05 1"
      rpy="0 0 0" />
    <parent
      link="base_link" />
    <child
      link="link1" />
    <axis
      xyz="1 0 0" />
    <limit
      lower="-1.57"
      upper="0"
      effort="10."
      velocity="1." />
    <dynamics damping="5" friction="0.0"/>

  </joint>
</robot>